Workbook

Sheet Rolling
A1: ECONOMIC SUMMARY
A3: SOCIAL WELFARE | E3: GENERAL
A4: Metric | B4: Total (EUR) | C4: Per Day (EUR) | E4: Average Executed Price EUR/MWh | F4: 110.68036
A5: Total Demand Value | B5: 2.8206081e+09 | C5: 94020269 | E5: Total Wind Curtailed (MWh) | F5: 3075.7789
A6: Total Generation Cost | B6: 3.6472935e+08 | C6: 12157645
A7: Social Welfare | B7: 2.4558787e+09 | C7: 81862624
A9: PRODUCER REVENUES (Executed-only)
A10: Generator | B10: Energy (MWh) | C10: Revenue (EUR) | D10: Avg Price | E10: Revenue/Day (EUR)
A11: Base | B11: 4014535.9 | C11: 4.5417385e+08 | D11: 113.13234 | E11: 15139128
A12: Mid | B12: 1678134.2 | C12: 2.4266119e+08 | D12: 144.60177 | E12: 8088706.3
A13: Peak | B13: 733616.88 | C13: 1.3505883e+08 | D13: 184.09995 | E13: 4501960.9
A14: Solar | B14: 484577.34 | C14: 41325270 | D14: 85.281061 | E14: 1377509
A15: Wind | B15: 2697773.5 | C15: 1.9026839e+08 | D15: 70.527933 | E15: 6342279.7
A16: Total | B16: 9608637.9 | C16: 1.0634875e+09 | E16: 35449584
A18: TOTAL FINANCIAL REVENUE (Incl. financial repositions → sum(q*price))
A19: Generator | B19: Net Revenue | C19: Net Traded | D19: Gross Traded | E19: Revenue/Day
A20: Base | B20: 4.2136384e+08 | C20: 4224535.9 | D20: 5762929.2 | E20: 14045461
A21: Mid | B21: 2.3549058e+08 | C21: 1809225.3 | D21: 4591651.1 | E21: 7849686
A22: Peak | B22: 1.3145567e+08 | C22: 774446.37 | D22: 5073931.5 | E22: 4381855.6
A23: Solar | B23: 38817872 | C23: 532300.62 | D23: 532300.62 | E23: 1293929.1
A24: Wind | B24: 1.4113207e+08 | C24: 2753954.6 | D24: 9156482.8 | E24: 4704402.2
A25: Total Net Revenue | B25: 9.6826002e+08 | E25: 32275334
A27: GENERATOR COSTS (Production Costs)
A28: Generator | B28: Total Cost (EUR) | C28: Cost/Day (EUR)
A29: Base | B29: 1.2043608e+08 | C29: 4014535.9
A30: Mid | B30: 1.3425074e+08 | C30: 4475024.6
A31: Peak | B31: 1.1004253e+08 | C31: 3668084.4
A32: Solar | B32: 0 | C32: 0
A33: Wind | B33: 0 | C33: 0
A34: Total System Cost | B34: 3.6472935e+08 | C34: 12157645
A35: Average per Clearing | B35: 523284.57
A37: GENERATOR PROFITS (Full Revenue - Cost)
A38: Generator | B38: Total Profit (EUR) | C38: Profit/Day (EUR)
A39: Base | B39: 3.0092776e+08 | C39: 10030925
A40: Mid | B40: 1.0123984e+08 | C40: 3374661.3
A41: Peak | B41: 21413136 | C41: 713771.19
A42: Solar | B42: 38817872 | C42: 1293929.1
A43: Wind | B43: 1.4113207e+08 | C43: 4704402.2
A44: Total Generator Profit | B44: 6.0353068e+08 | C44: 20117689
A46: STORAGE REVENUE
...

Sheet Fixed
A1: ECONOMIC SUMMARY
A3: SOCIAL WELFARE | E3: GENERAL
A4: Metric | B4: Total (EUR) | C4: Per Day (EUR) | E4: Average Executed Price in EUR/MWh | F4: 109.59772
A5: Total Demand Value | B5: 2.8210574e+09 | C5: 94035248 | E5: Total Wind Curtailed (MWh) | F5: 5474.9494
A6: Total Generation Cost | B6: 3.656556e+08 | C6: 12188520
A7: Social Welfare | B7: 2.4554018e+09 | C7: 81846728
A9: PRODUCER REVENUES (Executed-only)
A10: Generator | B10: Energy (MWh) | C10: Revenue (EUR) | D10: Avg Price | E10: Revenue/Day (EUR)
A11: Base | B11: 4018340.4 | C11: 4.5123762e+08 | D11: 112.29452 | E11: 15041254
A12: Mid | B12: 1682689 | C12: 2.4209971e+08 | D12: 143.87668 | E12: 8069990.4
A13: Peak | B13: 736601.78 | C13: 1.3612286e+08 | D13: 184.79844 | E13: 4537428.6
A14: Solar | B14: 484577.34 | C14: 40015442 | D14: 82.578029 | E14: 1333848.1
A15: Wind | B15: 2695374.4 | C15: 1.8458947e+08 | D15: 68.483798 | E15: 6152982.5
A16: Total | B16: 9617582.9 | C16: 1.0540651e+09 | E16: 35135504
A18: TOTAL FINANCIAL REVENUE (Incl. financial repositions → sum(q*price))
A19: Generator | B19: Net Revenue | C19: Net Traded | D19: Gross Traded | E19: Revenue/Day
A20: Base | B20: 4.6562282e+08 | C20: 4228340.4 | D20: 5119379.5 | E20: 15520761
A21: Mid | B21: 2.5669443e+08 | C21: 1813223.5 | D21: 3582473.4 | E21: 8556481
A22: Peak | B22: 1.3890313e+08 | C22: 778411.05 | D22: 3548825.7 | E22: 4630104.4
A23: Solar | B23: 43557827 | C23: 532300.62 | D23: 532300.62 | E23: 1451927.6
A24: Wind | B24: 1.667855e+08 | C24: 2750909.1 | D24: 7209854.4 | E24: 5559516.7
A25: Total Net Revenue | B25: 1.0715637e+09 | E25: 35718790
A27: GENERATOR COSTS (Production Costs)
A28: Generator | B28: Total Cost (EUR) | C28: Cost/Day (EUR)
A29: Base | B29: 1.2055021e+08 | C29: 4018340.4
A30: Mid | B30: 1.3461512e+08 | C30: 4487170.7
A31: Peak | B31: 1.1049027e+08 | C31: 3683008.9
A32: Solar | B32: 0 | C32: 0
A33: Wind | B33: 0 | C33: 0
A34: Total System Cost | B34: 3.656556e+08 | C34: 12188520
A35: Average per Clearing | B35: 524613.48
A37: GENERATOR PROFITS (Full Revenue - Cost)
A38: Generator | B38: Total Profit (EUR) | C38: Profit/Day (EUR)
A39: Base | B39: 3.4507261e+08 | C39: 11502420
A40: Mid | B40: 1.2207931e+08 | C40: 4069310.3
A41: Peak | B41: 28412864 | C41: 947095.48
A42: Solar | B42: 43557827 | C42: 1451927.6
A43: Wind | B43: 1.667855e+08 | C43: 5559516.7
A44: Total Generator Profit | B44: 7.0590811e+08 | C44: 23530270
A46: STORAGE REVENUE
...

Sheet Comparison
B1: Rolling | C1: Fixed | D1: Changes
A2: Total system costs per day | B2: =Rolling!C34 -> 12157645 | C2: =Fixed!C34 -> 12188520 | D2: =(C2-B2)/B2 -> 0.0025395568
A3: Net storage revenue/day | B3: =Rolling!C54 -> 309528.93 | C3: =Fixed!C54 -> 347683.02 | D3: =(C3-B3)/B3 -> 0.12326505
A4: Social welfare per day | B4: =Rolling!C7 -> 81862624 | C4: =Fixed!C7 -> 81846728 | D4: =(C4-B4)/B4 -> -0.00019417971
A5: Net revenue/day
A6: Base | B6: =Rolling!E20 -> 14045461 | C6: =Fixed!E20 -> 15520761 | D6: =(C6-B6)/B6 -> 0.10503745
A7: Mid | B7: =Rolling!E21 -> 7849686 | C7: =Fixed!E21 -> 8556481 | D7: =(C7-B7)/B7 -> 0.090041184
A8: Peak | B8: =Rolling!E22 -> 4381855.6 | C8: =Fixed!E22 -> 4630104.4 | D8: =(C8-B8)/B8 -> 0.056653806
A9: Solar | B9: =Rolling!E23 -> 1293929.1 | C9: =Fixed!E23 -> 1451927.6 | D9: =(C9-B9)/B9 -> 0.12210753
A10: Wind | B10: =Rolling!E24 -> 4704402.2 | C10: =Fixed!E24 -> 5559516.7 | D10: =(C10-B10)/B10 -> 0.18176901
