Workbook

Sheet clear_freq=1
A1: ECONOMIC SUMMARY
A3: PRODUCER REVENUES (Executed-only)
A4: Generator | B4: Energy (MWh) | C4: Revenue (EUR) | D4: Avg Price | E4: Revenue/Day (EUR)
A5: Base | B5: 697000 | C5: 62009815 | D5: 88.966736 | E5: 2066993.8
A6: Mid | B6: 325072.17 | C6: 29241215 | D6: 89.952994 | E6: 974707.15
A7: Peak | B7: 64715.027 | C7: 6471502.7 | D7: 100 | E7: 215716.76
A8: Solar | B8: 60030 | C8: 6003000 | D8: 100 | E8: 200100
A9: Wind | B9: 312150 | C9: 28031839 | D9: 89.802463 | E9: 934394.63
A10: Total | B10: 1458967.2 | C10: 1.3175737e+08 | E10: 4391912.4
A12: TOTAL FINANCIAL REVENUE (Incl. financial repositions → sum(q*price))
A13: Generator | B13: Net Revenue | C13: Net Traded | D13: Gross Traded | E13: Revenue/Day
A14: Base | B14: 56406672 | C14: 720000 | D14: 720000 | E14: 1880222.4
A15: Mid | B15: 29604286 | C15: 335951.66 | D15: 1093991.1 | E15: 986809.53
A16: Peak | B16: 11063522 | C16: 67276.122 | D16: 1501739.3 | E16: 368784.07
A17: Solar | B17: 5489585.6 | C17: 62100 | D17: 62100 | E17: 182986.19
A18: Wind | B18: 12546795 | C18: 322187.82 | D18: 2833464 | E18: 418226.5
A19: Total Net Revenue | B19: 1.1511086e+08 | E19: 3837028.7
A21: GENERATOR COSTS (Production Costs)
A22: Generator | B22: Total Cost (EUR) | C22: Cost/Day (EUR)
A23: Base | B23: 20910000 | C23: 697000
A24: Mid | B24: 19504330 | C24: 650144.33
A25: Peak | B25: 6471502.7 | C25: 215716.76
A26: Solar | B26: 0 | C26: 0
A27: Wind | B27: 0 | C27: 0
A28: Total System Cost | B28: 46885833 | C28: 1562861.1
A29: Average per Clearing | B29: 67171.68
A31: GENERATOR PROFITS (Full Revenue - Cost)
A32: Generator | B32: Total Profit (EUR) | C32: Profit/Day (EUR)
A33: Base | B33: 35496672 | C33: 1183222.4
A34: Mid | B34: 10099956 | C34: 336665.2
A35: Peak | B35: 4592019.2 | C35: 153067.31
A36: Solar | B36: 5489585.6 | C36: 182986.19
A37: Wind | B37: 12546795 | C37: 418226.5
A38: Total Generator Profit | B38: 68225028 | C38: 2274167.6
A40: STORAGE REVENUE
A41: Metric | B41: Total | C41: Per Day
A42: Energy Discharged (MWh) | B42: 19100.858 | C42: 636.69527
A43: Energy Charged (MWh) | B43: 23646.473 | C43: 788.21577
A44: Avg Discharge Price (EUR/MWh) | B44: 99.589435
A45: Avg Charging Price (EUR/MWh) | B45: 67.548347
...

Sheet clear_freq=3
A1: ECONOMIC SUMMARY
A3: PRODUCER REVENUES (Executed-only)
A4: Generator | B4: Energy (MWh) | C4: Revenue (EUR) | D4: Avg Price | E4: Revenue/Day (EUR)
A5: Base | B5: 698000 | C5: 59078296 | D5: 84.639393 | E5: 1969276.5
A6: Mid | B6: 329197.92 | C6: 28266551 | D6: 85.864915 | E6: 942218.37
A7: Peak | B7: 62263.729 | C7: 6226372.9 | D7: 100 | E7: 207545.76
A8: Solar | B8: 60030 | C8: 6003000 | D8: 100 | E8: 200100
A9: Wind | B9: 312350 | C9: 26750693 | D9: 85.643325 | E9: 891689.75
A10: Total | B10: 1461841.6 | C10: 1.2632491e+08 | E10: 4210830.4
A12: TOTAL FINANCIAL REVENUE (Incl. financial repositions → sum(q*price))
A13: Generator | B13: Net Revenue | C13: Net Traded | D13: Gross Traded | E13: Revenue/Day
A14: Base | B14: 58179726 | C14: 719000 | D14: 719000 | E14: 1939324.2
A15: Mid | B15: 28827171 | C15: 339001.05 | D15: 558306.79 | E15: 960905.68
A16: Peak | B16: 7609351.6 | C16: 64629.643 | D16: 504955.84 | E16: 253645.05
A17: Solar | B17: 5773578.9 | C17: 62100 | D17: 62100 | E17: 192452.63
A18: Wind | B18: 21889211 | C18: 322126.53 | D18: 1120525 | E18: 729640.36
A19: Total Net Revenue | B19: 1.2227904e+08 | E19: 4075967.9
A21: GENERATOR COSTS (Production Costs)
A22: Generator | B22: Total Cost (EUR) | C22: Cost/Day (EUR)
A23: Base | B23: 20940000 | C23: 698000
A24: Mid | B24: 19751875 | C24: 658395.84
A25: Peak | B25: 6226372.9 | C25: 207545.76
A26: Solar | B26: 0 | C26: 0
A27: Wind | B27: 0 | C27: 0
A28: Total System Cost | B28: 46918248 | C28: 1563941.6
A29: Average per Clearing | B29: 201365.87
A31: GENERATOR PROFITS (Full Revenue - Cost)
A32: Generator | B32: Total Profit (EUR) | C32: Profit/Day (EUR)
A33: Base | B33: 37239726 | C33: 1241324.2
A34: Mid | B34: 9075295.5 | C34: 302509.85
A35: Peak | B35: 1382978.7 | C35: 46099.292
A36: Solar | B36: 5773578.9 | C36: 192452.63
A37: Wind | B37: 21889211 | C37: 729640.36
A38: Total Generator Profit | B38: 75360790 | C38: 2512026.3
A40: STORAGE REVENUE
A41: Metric | B41: Total | C41: Per Day
A42: Energy Discharged (MWh) | B42: 20991.248 | C42: 699.70826
A43: Energy Charged (MWh) | B43: 26486.762 | C43: 882.89208
A44: Avg Discharge Price (EUR/MWh) | B44: 99.84183
A45: Avg Charging Price (EUR/MWh) | B45: 59.688373
...

Sheet clear_freq=6
A1: ECONOMIC SUMMARY
A3: PRODUCER REVENUES (Executed-only)
A4: Generator | B4: Energy (MWh) | C4: Revenue (EUR) | D4: Avg Price | E4: Revenue/Day (EUR)
A5: Base | B5: 701000 | C5: 58848000 | D5: 83.948645 | E5: 1961600
A6: Mid | B6: 329818.05 | C6: 28183083 | D6: 85.450396 | E6: 939436.1
A7: Peak | B7: 62097.881 | C7: 6209788.1 | D7: 100 | E7: 206992.94
A8: Solar | B8: 60030 | C8: 6003000 | D8: 100 | E8: 200100
A9: Wind | B9: 313250 | C9: 26572050 | D9: 84.826975 | E9: 885735
A10: Total | B10: 1466195.9 | C10: 1.2581592e+08 | E10: 4193864
A12: TOTAL FINANCIAL REVENUE (Incl. financial repositions → sum(q*price))
A13: Generator | B13: Net Revenue | C13: Net Traded | D13: Gross Traded | E13: Revenue/Day
A14: Base | B14: 59566693 | C14: 719000 | D14: 719000 | E14: 1985556.4
A15: Mid | B15: 29048112 | C15: 338443.04 | D15: 413806.62 | E15: 968270.41
A16: Peak | B16: 6971152 | C16: 65167.545 | D16: 253295.18 | E16: 232371.73
A17: Solar | B17: 5926230 | C17: 62100 | D17: 62100 | E17: 197541
A18: Wind | B18: 25117791 | C18: 321282.44 | D18: 656557.71 | E18: 837259.68
A19: Total Net Revenue | B19: 1.2662998e+08 | E19: 4220999.2
A21: GENERATOR COSTS (Production Costs)
A22: Generator | B22: Total Cost (EUR) | C22: Cost/Day (EUR)
A23: Base | B23: 21030000 | C23: 701000
A24: Mid | B24: 19789083 | C24: 659636.1
A25: Peak | B25: 6209788.1 | C25: 206992.94
A26: Solar | B26: 0 | C26: 0
A27: Wind | B27: 0 | C27: 0
A28: Total System Cost | B28: 47028871 | C28: 1567629
A29: Average per Clearing | B29: 401956.16
A31: GENERATOR PROFITS (Full Revenue - Cost)
A32: Generator | B32: Total Profit (EUR) | C32: Profit/Day (EUR)
A33: Base | B33: 38536693 | C33: 1284556.4
A34: Mid | B34: 9259029.3 | C34: 308634.31
A35: Peak | B35: 761363.86 | C35: 25378.795
A36: Solar | B36: 5926230 | C36: 197541
A37: Wind | B37: 25117791 | C37: 837259.68
A38: Total Generator Profit | B38: 79601106 | C38: 2653370.2
A40: STORAGE REVENUE
A41: Metric | B41: Total | C41: Per Day
A42: Energy Discharged (MWh) | B42: 19972.119 | C42: 665.73729
A43: Energy Charged (MWh) | B43: 25368.048 | C43: 845.60159
A44: Avg Discharge Price (EUR/MWh) | B44: 100
A45: Avg Charging Price (EUR/MWh) | B45: 60.289735
...

Sheet Comparison
B1: Reclearing frequency | E1: Changes
B2: 1 | C2: 3 | D2: 6 | E2: 1-3h change | F2: h
A3: Total system costs per day | B3: ='clear_freq=1'!C28 -> 1562861.1 | C3: ='clear_freq=3'!C28 -> 1563941.6 | D3: ='clear_freq=6'!C28 -> 1567629 | E3: =(C3-B3)/B3 -> 0.00069136478 | F3: =(D3-B3)/B3 -> 0.0030507782
A4: Net storage revenue/day | B4: ='clear_freq=1'!C48 -> 10165.45 | C4: ='clear_freq=3'!C48 -> 17161.761 | D4: ='clear_freq=6'!C48 -> 15592.633 | E4: =(C4-B4)/B4 -> 0.68824406 | F4: =(D4-B4)/B4 -> 0.53388519
A5: Gross traded volume/day
A6: Base | B6: ='clear_freq=1'!D14 -> 720000 | C6: 720000 | D6: 720000 | E6: =(C6-B6)/B6 -> 0 | F6: =(D6-B6)/B6 -> 0
A7: Mid | B7: ='clear_freq=1'!D15 -> 1093991.1 | C7: ='clear_freq=3'!D15 -> 558306.79 | D7: ='clear_freq=6'!D15 -> 413806.62 | E7: =(C7-B7)/B7 -> -0.48966056 | F7: =(D7-B7)/B7 -> -0.62174589
A8: Peak | B8: ='clear_freq=1'!D16 -> 1501739.3 | C8: ='clear_freq=3'!D16 -> 504955.84 | D8: ='clear_freq=6'!D16 -> 253295.18 | E8: =(C8-B8)/B8 -> -0.66375267 | F8: =(D8-B8)/B8 -> -0.83133213
A9: Solar | B9: ='clear_freq=1'!D17 -> 62100 | C9: ='clear_freq=3'!D17 -> 62100 | D9: ='clear_freq=6'!D17 -> 62100 | E9: =(C9-B9)/B9 -> 0 | F9: =(D9-B9)/B9 -> 0
A10: Wind | B10: ='clear_freq=1'!D18 -> 2833464 | C10: ='clear_freq=3'!D18 -> 1120525 | D10: ='clear_freq=6'!D18 -> 656557.71 | E10: =(C10-B10)/B10 -> -0.60453883 | F10: =(D10-B10)/B10 -> -0.76828444
