Workbook

Sheet Rolling
A1: ECONOMIC SUMMARY
A3: SOCIAL WELFARE | E3: GENERAL
A4: Metric | B4: Total (EUR) | C4: Per Day (EUR) | E4: Average Executed Price EUR/MWh | F4: 34.941282
A5: Total Demand Value | B5: 2.3638586e+09 | C5: 78795286 | E5: Total Wind Curtailed (MWh) | F5: 477425.89
A6: Total Generation Cost | B6: 90380170 | C6: 3012672.3
A7: Social Welfare | B7: 2.2734784e+09 | C7: 75782613
A9: PRODUCER REVENUES (Executed-only)
A10: Generator | B10: Energy (MWh) | C10: Revenue (EUR) | D10: Avg Price | E10: Revenue/Day (EUR)
A11: Base | B11: 2441670.3 | C11: 1.4421625e+08 | D11: 59.06459 | E11: 4807208.5
A12: Mid | B12: 209105.81 | C12: 17941127 | D12: 85.799278 | E12: 598037.58
A13: Peak | B13: 2677.3131 | C13: 401596.96 | D13: 150 | E13: 13386.565
A14: Solar | B14: 3345677.4 | C14: 42285189 | D14: 12.638752 | E14: 1409506.3
A15: Wind | B15: 2406153.6 | C15: 88847245 | D15: 36.92501 | E15: 2961574.8
A16: Total | B16: 8405284.4 | C16: 2.9369141e+08 | E16: 9789713.7
A18: TOTAL FINANCIAL REVENUE (Incl. financial repositions → sum(q*price))
A19: Generator | B19: Net Revenue | C19: Net Traded | D19: Gross Traded | E19: Revenue/Day
A20: Base | B20: 1.3437438e+08 | C20: 2590223.1 | D20: 5164434.1 | E20: 4479146
A21: Mid | B21: 21915222 | C21: 243412.34 | D21: 3036661.7 | E21: 730507.39
A22: Peak | B22: 401596.96 | C22: 2677.3131 | D22: 6681.9029 | E22: 13386.565
A23: Solar | B23: 28935137 | C23: 3511488.9 | D23: 3633866.6 | E23: 964504.57
A24: Wind | B24: 59426002 | C24: 2439377.9 | D24: 8414383.4 | E24: 1980866.7
A25: Total Net Revenue | B25: 2.4505234e+08 | E25: 8168411.2
A27: GENERATOR COSTS (Production Costs)
A28: Generator | B28: Total Cost (EUR) | C28: Cost/Day (EUR)
A29: Base | B29: 73250108 | C29: 2441670.3
A30: Mid | B30: 16728465 | C30: 557615.49
A31: Peak | B31: 401596.96 | C31: 13386.565
A32: Solar | B32: 0 | C32: 0
A33: Wind | B33: 0 | C33: 0
A34: Total System Cost | B34: 90380170 | C34: 3012672.3
A35: Average per Clearing | B35: 129670.26
A37: GENERATOR PROFITS (Full Revenue - Cost)
A38: Generator | B38: Total Profit (EUR) | C38: Profit/Day (EUR)
A39: Base | B39: 61124271 | C39: 2037475.7
A40: Mid | B40: 5186757.2 | C40: 172891.91
A41: Peak | B41: 0 | C41: 0
A42: Solar | B42: 28935137 | C42: 964504.57
A43: Wind | B43: 59426002 | C43: 1980866.7
A44: Total Generator Profit | B44: 1.5467217e+08 | C44: 5155738.9
A46: STORAGE REVENUE
...

Sheet Fixed
A1: ECONOMIC SUMMARY
A3: SOCIAL WELFARE | E3: GENERAL
A4: Metric | B4: Total (EUR) | C4: Per Day (EUR) | E4: Average Executed Price in EUR/MWh | F4: 34.775903
A5: Total Demand Value | B5: 2.3635021e+09 | C5: 78783405 | E5: Total Wind Curtailed (MWh) | F5: 482300.74
A6: Total Generation Cost | B6: 90496155 | C6: 3016538.5
A7: Social Welfare | B7: 2.273006e+09 | C7: 75766866
A9: PRODUCER REVENUES (Executed-only)
A10: Generator | B10: Energy (MWh) | C10: Revenue (EUR) | D10: Avg Price | E10: Revenue/Day (EUR)
A11: Base | B11: 2435689.5 | C11: 1.4416788e+08 | D11: 59.189759 | E11: 4805595.9
A12: Mid | B12: 211942.7 | C12: 18801183 | D12: 88.708804 | E12: 626706.11
A13: Peak | B13: 3133.6853 | C13: 470052.8 | D13: 150 | E13: 15668.427
A14: Solar | B14: 3347229.9 | C14: 39747548 | D14: 11.874759 | E14: 1324918.3
A15: Wind | B15: 2401278.7 | C15: 88905696 | D15: 37.024313 | E15: 2963523.2
A16: Total | B16: 8399274.5 | C16: 2.9209236e+08 | E16: 9736411.9
A18: TOTAL FINANCIAL REVENUE (Incl. financial repositions → sum(q*price))
A19: Generator | B19: Net Revenue | C19: Net Traded | D19: Gross Traded | E19: Revenue/Day
A20: Base | B20: 1.4681534e+08 | C20: 2583929.3 | D20: 4651893.8 | E20: 4893844.7
A21: Mid | B21: 21801741 | C21: 245201.22 | D21: 2110674.4 | E21: 726724.71
A22: Peak | B22: 475374.38 | C22: 3133.6853 | D22: 7671.4185 | E22: 15845.813
A23: Solar | B23: 39289751 | C23: 3513041.4 | D23: 3633420.6 | E23: 1309658.4
A24: Wind | B24: 72493982 | C24: 2435823.5 | D24: 6984529.6 | E24: 2416466.1
A25: Total Net Revenue | B25: 2.8087619e+08 | E25: 9362539.7
A27: GENERATOR COSTS (Production Costs)
A28: Generator | B28: Total Cost (EUR) | C28: Cost/Day (EUR)
A29: Base | B29: 73070686 | C29: 2435689.5
A30: Mid | B30: 16955416 | C30: 565180.53
A31: Peak | B31: 470052.8 | C31: 15668.427
A32: Solar | B32: 0 | C32: 0
A33: Wind | B33: 0 | C33: 0
A34: Total System Cost | B34: 90496155 | C34: 3016538.5
A35: Average per Clearing | B35: 129836.66
A37: GENERATOR PROFITS (Full Revenue - Cost)
A38: Generator | B38: Total Profit (EUR) | C38: Profit/Day (EUR)
A39: Base | B39: 73744656 | C39: 2458155.2
A40: Mid | B40: 4846325.2 | C40: 161544.17
A41: Peak | B41: 5321.5758 | C41: 177.38586
A42: Solar | B42: 39289751 | C42: 1309658.4
A43: Wind | B43: 72493982 | C43: 2416466.1
A44: Total Generator Profit | B44: 1.9038004e+08 | C44: 6346001.2
A46: STORAGE REVENUE
...

Sheet Comparison
B1: Rolling | C1: Fixed | D1: Changes
A2: Total system costs per day | B2: =Rolling!C34 -> 3012672.3 | C2: =Fixed!C34 -> 3016538.5 | D2: =(C2-B2)/B2 -> 0.0012832989
A3: Social welfare per day | B3: =Rolling!C7 -> 75782613 | C3: =Fixed!C7 -> 75766866 | D3: =(C3-B3)/B3 -> -0.00020779498
A4: Curtailment | B4: =Rolling!F5 -> 477425.89 | C4: =Fixed!F5 -> 482300.74 | D4: =(C4-B4)/B4 -> 0.010210684
A5: Net storage revenue/day | B5: =Rolling!C54 -> 331832.76 | C5: =Fixed!C54 -> 315073.97 | D5: =(C5-B5)/B5 -> -0.050503721
A6: Profit/day
A7: Base | B7: =Rolling!B39 -> 61124271 | C7: =Fixed!B39 -> 73744656 | D7: =(C7-B7)/B7 -> 0.20647092
A8: Mid | B8: =Rolling!B40 -> 5186757.2 | C8: =Fixed!B40 -> 4846325.2 | D8: =(C8-B8)/B8 -> -0.065634838
A9: Peak | B9: =Rolling!B41 -> 0 | C9: =Fixed!B41 -> 5321.5758 | D9: =(C9-B9)/B9 -> #DIV/0!
A10: Solar | B10: =Rolling!B42 -> 28935137 | C10: =Fixed!B42 -> 39289751 | D10: =(C10-B10)/B10 -> 0.35785606
A11: Wind | B11: =Rolling!B43 -> 59426002 | C11: =Fixed!B43 -> 72493982 | D11: =(C11-B11)/B11 -> 0.2199034
